current conda env is /global/scratch/users/chenxin0210/conda-env/rl-ddop
================
current GPU condition is:
2.1.0+cu121
12.1
CUDA is available!
Number of GPUs: 3
Device 0: NVIDIA A40
Device 1: NVIDIA A40
Device 2: NVIDIA A40
available nCPU is:
10
================
start running:
The following values were not passed to `accelerate launch` and had defaults used instead:
	`--num_processes` was set to a value of `3`
		More than one GPU was found, enabling multi-GPU training.
		If this was unintended please pass in `--num_processes=1`.
	`--num_machines` was set to a value of `1`
	`--mixed_precision` was set to a value of `'no'`
	`--dynamo_backend` was set to a value of `'no'`
To avoid this warning pass in values for each of the problematic parameters or run `accelerate config`.
wandb: Currently logged in as: cx9. Use `wandb login --relogin` to force relogin
wandb: Appending key for api.wandb.ai to your netrc file: /global/home/users/chenxin0210/.netrc
wandb: ERROR Unable to read ~/.netrc
wandb: Currently logged in as: cx9. Use `wandb login --relogin` to force relogin
wandb: Currently logged in as: cx9. Use `wandb login --relogin` to force relogin
wandb: Appending key for api.wandb.ai to your netrc file: /global/home/users/chenxin0210/.netrc
wandb: ERROR Unable to read ~/.netrc
wandb: Appending key for api.wandb.ai to your netrc file: /global/home/users/chenxin0210/.netrc
wandb: ERROR Unable to read ~/.netrc
wandb: - Waiting for wandb.init()...wandb: \ Waiting for wandb.init()...Traceback (most recent call last):
  File "/global/scratch/users/chenxin0210/ddpo-pytorch/scripts/train.py", line 511, in <module>
    app.run(main)
  File "/global/scratch/users/chenxin0210/conda-env/rl-ddop/lib/python3.10/site-packages/absl/app.py", line 308, in run
    _run_main(main, args)
  File "/global/scratch/users/chenxin0210/conda-env/rl-ddop/lib/python3.10/site-packages/absl/app.py", line 254, in _run_main
    sys.exit(main(argv))
  File "/global/scratch/users/chenxin0210/ddpo-pytorch/scripts/train.py", line 87, in main
    pipeline = StableDiffusionPipeline.from_pretrained(config.pretrained.model, revision=config.pretrained.revision)
  File "/global/scratch/users/chenxin0210/conda-env/rl-ddop/lib/python3.10/site-packages/diffusers/pipelines/pipeline_utils.py", line 908, in from_pretrained
    cached_folder = cls.download(
  File "/global/scratch/users/chenxin0210/conda-env/rl-ddop/lib/python3.10/site-packages/diffusers/pipelines/pipeline_utils.py", line 1349, in download
    cached_folder = snapshot_download(
  File "/global/scratch/users/chenxin0210/conda-env/rl-ddop/lib/python3.10/site-packages/huggingface_hub/utils/_validators.py", line 118, in _inner_fn
    return fn(*args, **kwargs)
  File "/global/scratch/users/chenxin0210/conda-env/rl-ddop/lib/python3.10/site-packages/huggingface_hub/_snapshot_download.py", line 207, in snapshot_download
    with open(ref_path, "w") as f:
OSError: [Errno 122] Disk quota exceeded: '/global/home/users/chenxin0210/.cache/huggingface/hub/models--CompVis--stable-diffusion-v1-4/refs/main'
Traceback (most recent call last):
  File "/global/scratch/users/chenxin0210/ddpo-pytorch/scripts/train.py", line 511, in <module>
    app.run(main)
  File "/global/scratch/users/chenxin0210/conda-env/rl-ddop/lib/python3.10/site-packages/absl/app.py", line 308, in run
    _run_main(main, args)
  File "/global/scratch/users/chenxin0210/conda-env/rl-ddop/lib/python3.10/site-packages/absl/app.py", line 254, in _run_main
    sys.exit(main(argv))
  File "/global/scratch/users/chenxin0210/ddpo-pytorch/scripts/train.py", line 87, in main
    pipeline = StableDiffusionPipeline.from_pretrained(config.pretrained.model, revision=config.pretrained.revision)
  File "/global/scratch/users/chenxin0210/conda-env/rl-ddop/lib/python3.10/site-packages/diffusers/pipelines/pipeline_utils.py", line 908, in from_pretrained
    cached_folder = cls.download(
  File "/global/scratch/users/chenxin0210/conda-env/rl-ddop/lib/python3.10/site-packages/diffusers/pipelines/pipeline_utils.py", line 1349, in download
    cached_folder = snapshot_download(
  File "/global/scratch/users/chenxin0210/conda-env/rl-ddop/lib/python3.10/site-packages/huggingface_hub/utils/_validators.py", line 118, in _inner_fn
    return fn(*args, **kwargs)
  File "/global/scratch/users/chenxin0210/conda-env/rl-ddop/lib/python3.10/site-packages/huggingface_hub/_snapshot_download.py", line 207, in snapshot_download
    with open(ref_path, "w") as f:
OSError: [Errno 122] Disk quota exceeded: '/global/home/users/chenxin0210/.cache/huggingface/hub/models--CompVis--stable-diffusion-v1-4/refs/main'
[2023-10-22 14:53:05,218] torch.distributed.elastic.multiprocessing.api: [WARNING] Sending process 19282 closing signal SIGTERM
[2023-10-22 14:53:05,382] torch.distributed.elastic.multiprocessing.api: [ERROR] failed (exitcode: 1) local_rank: 1 (pid: 19283) of binary: /global/scratch/users/chenxin0210/conda-env/rl-ddop/bin/python
Traceback (most recent call last):
  File "/global/scratch/users/chenxin0210/conda-env/rl-ddop/bin/accelerate", line 8, in <module>
    sys.exit(main())
  File "/global/scratch/users/chenxin0210/conda-env/rl-ddop/lib/python3.10/site-packages/accelerate/commands/accelerate_cli.py", line 45, in main
    args.func(args)
  File "/global/scratch/users/chenxin0210/conda-env/rl-ddop/lib/python3.10/site-packages/accelerate/commands/launch.py", line 906, in launch_command
    multi_gpu_launcher(args)
  File "/global/scratch/users/chenxin0210/conda-env/rl-ddop/lib/python3.10/site-packages/accelerate/commands/launch.py", line 599, in multi_gpu_launcher
    distrib_run.run(args)
  File "/global/scratch/users/chenxin0210/conda-env/rl-ddop/lib/python3.10/site-packages/torch/distributed/run.py", line 797, in run
    elastic_launch(
  File "/global/scratch/users/chenxin0210/conda-env/rl-ddop/lib/python3.10/site-packages/torch/distributed/launcher/api.py", line 134, in __call__
    return launch_agent(self._config, self._entrypoint, list(args))
  File "/global/scratch/users/chenxin0210/conda-env/rl-ddop/lib/python3.10/site-packages/torch/distributed/launcher/api.py", line 264, in launch_agent
    raise ChildFailedError(
torch.distributed.elastic.multiprocessing.errors.ChildFailedError: 
============================================================
scripts/train.py FAILED
------------------------------------------------------------
Failures:
[1]:
  time      : 2023-10-22_14:53:05
  host      : n0000.es1
  rank      : 2 (local_rank: 2)
  exitcode  : 1 (pid: 19284)
  error_file: <N/A>
  traceback : To enable traceback see: https://pytorch.org/docs/stable/elastic/errors.html
------------------------------------------------------------
Root Cause (first observed failure):
[0]:
  time      : 2023-10-22_14:53:05
  host      : n0000.es1
  rank      : 1 (local_rank: 1)
  exitcode  : 1 (pid: 19283)
  error_file: <N/A>
  traceback : To enable traceback see: https://pytorch.org/docs/stable/elastic/errors.html
============================================================
